09-10 15:20:58 jdbc[2]: exception
org.h2.jdbc.JdbcSQLException: Column "1234" not found; SQL statement:
SELECT sessionId FROM Persons WHERE sessionId = "1234" [42122-168]
	at org.h2.message.DbException.getJdbcSQLException(DbException.java:329)
	at org.h2.message.DbException.get(DbException.java:169)
	at org.h2.message.DbException.get(DbException.java:146)
	at org.h2.expression.ExpressionColumn.optimize(ExpressionColumn.java:138)
	at org.h2.expression.Comparison.optimize(Comparison.java:161)
	at org.h2.command.dml.Select.prepare(Select.java:802)
	at org.h2.command.Parser.prepareCommand(Parser.java:218)
	at org.h2.engine.Session.prepareLocal(Session.java:415)
	at org.h2.engine.Session.prepareCommand(Session.java:364)
	at org.h2.jdbc.JdbcConnection.prepareCommand(JdbcConnection.java:1109)
	at org.h2.jdbc.JdbcStatement.executeInternal(JdbcStatement.java:164)
	at org.h2.jdbc.JdbcStatement.execute(JdbcStatement.java:152)
	at org.h2.server.web.WebApp.getResult(WebApp.java:1311)
	at org.h2.server.web.WebApp.query(WebApp.java:1001)
	at org.h2.server.web.WebApp$1.next(WebApp.java:964)
	at org.h2.server.web.WebApp$1.next(WebApp.java:967)
	at org.h2.server.web.WebThread.process(WebThread.java:166)
	at org.h2.server.web.WebThread.run(WebThread.java:93)
	at java.lang.Thread.run(Thread.java:680)
09-10 15:22:14 jdbc[2]: exception
org.h2.jdbc.JdbcSQLException: Column "1234" not found; SQL statement:
SELECT sessionID  FROM Persons where sessionid="1234" [42122-168]
	at org.h2.message.DbException.getJdbcSQLException(DbException.java:329)
	at org.h2.message.DbException.get(DbException.java:169)
	at org.h2.message.DbException.get(DbException.java:146)
	at org.h2.expression.ExpressionColumn.optimize(ExpressionColumn.java:138)
	at org.h2.expression.Comparison.optimize(Comparison.java:161)
	at org.h2.command.dml.Select.prepare(Select.java:802)
	at org.h2.command.Parser.prepareCommand(Parser.java:218)
	at org.h2.engine.Session.prepareLocal(Session.java:415)
	at org.h2.engine.Session.prepareCommand(Session.java:364)
	at org.h2.jdbc.JdbcConnection.prepareCommand(JdbcConnection.java:1109)
	at org.h2.jdbc.JdbcStatement.executeInternal(JdbcStatement.java:164)
	at org.h2.jdbc.JdbcStatement.execute(JdbcStatement.java:152)
	at org.h2.server.web.WebApp.getResult(WebApp.java:1311)
	at org.h2.server.web.WebApp.query(WebApp.java:1001)
	at org.h2.server.web.WebApp$1.next(WebApp.java:964)
	at org.h2.server.web.WebApp$1.next(WebApp.java:967)
	at org.h2.server.web.WebThread.process(WebThread.java:166)
	at org.h2.server.web.WebThread.run(WebThread.java:93)
	at java.lang.Thread.run(Thread.java:680)
09-11 14:46:11 jdbc[2]: exception
org.h2.jdbc.JdbcSQLException: Syntax error in SQL statement "INSERT INTO AIRAVATA_USER (LASTNAME, FIRSTNAME , USERID , PASSWORD ) VALUE[*] ('Jayasekara', 'Amila', 'amilaj', 'secret') "; expected "DIRECT, SORTED, DEFAULT, VALUES, SET, (, SELECT, FROM"; SQL statement:
insert into airavata_user (LastName, firstname , userid , password ) value ('Jayasekara', 'Amila', 'amilaj', 'secret') [42001-168]
09-11 14:46:44 jdbc[2]: exception
org.h2.jdbc.JdbcSQLException: Syntax error in SQL statement "INSERT INTO AIRAVATA_USER (LASTNAME, FIRSTNAME , USERID , PASSWORD ) VALUE[*] ('Jayasekara', 'Amila', 'amilaj', 'secret') "; expected "DIRECT, SORTED, DEFAULT, VALUES, SET, (, SELECT, FROM"; SQL statement:
insert into airavata_user (LastName, firstname , userid , password ) value ('Jayasekara', 'Amila', 'amilaj', 'secret') [42001-168]
09-11 14:46:48 jdbc[2]: exception
org.h2.jdbc.JdbcSQLException: Syntax error in SQL statement "INSERT INTO AIRAVATA_USER (LASTNAME, FIRSTNAME , USERID , PASSWORD ) VALUE[*] ('Jayasekara', 'Amila', 'amilaj', 'secret') "; expected "DIRECT, SORTED, DEFAULT, VALUES, SET, (, SELECT, FROM"; SQL statement:
insert into airavata_user (LastName, firstname , userid , password ) value ('Jayasekara', 'Amila', 'amilaj', 'secret') [42001-168]
11-14 16:22:34 jdbc[4]: null
org.h2.message.DbException: The connection was not closed by the application and is garbage collected [90018-168]
	at org.h2.message.DbException.get(DbException.java:169)
	at org.h2.message.DbException.get(DbException.java:146)
	at org.h2.message.DbException.get(DbException.java:135)
	at org.h2.jdbc.JdbcConnection.closeOld(JdbcConnection.java:172)
	at org.h2.jdbc.JdbcConnection.<init>(JdbcConnection.java:119)
	at org.h2.jdbc.JdbcConnection.<init>(JdbcConnection.java:92)
	at org.h2.Driver.connect(Driver.java:72)
	at java.sql.DriverManager.getConnection(DriverManager.java:582)
	at java.sql.DriverManager.getConnection(DriverManager.java:154)
	at org.apache.airavata.security.util.DBLookup.getConnection(DBLookup.java:105)
	at org.apache.airavata.security.util.DBLookup.getMatchingColumnValue(DBLookup.java:60)
	at org.apache.airavata.security.util.DBLookup.getMatchingColumnValue(DBLookup.java:47)
	at org.apache.airavata.security.userstore.SessionDBUserStore.authenticate(SessionDBUserStore.java:64)
	at org.apache.airavata.security.userstore.SessionDBUserStoreTest.testAuthenticateFailure(SessionDBUserStoreTest.java:58)
	at sun.reflect.NativeMethodAccessorImpl.invoke0(Native Method)
	at sun.reflect.NativeMethodAccessorImpl.invoke(NativeMethodAccessorImpl.java:39)
	at sun.reflect.DelegatingMethodAccessorImpl.invoke(DelegatingMethodAccessorImpl.java:25)
	at java.lang.reflect.Method.invoke(Method.java:597)
	at junit.framework.TestCase.runTest(TestCase.java:168)
	at junit.framework.TestCase.runBare(TestCase.java:134)
	at junit.framework.TestResult$1.protect(TestResult.java:110)
	at junit.framework.TestResult.runProtected(TestResult.java:128)
	at junit.framework.TestResult.run(TestResult.java:113)
	at junit.framework.TestCase.run(TestCase.java:124)
	at junit.framework.TestSuite.runTest(TestSuite.java:232)
	at junit.framework.TestSuite.run(TestSuite.java:227)
	at org.junit.internal.runners.JUnit38ClassRunner.run(JUnit38ClassRunner.java:83)
	at org.apache.maven.surefire.junit4.JUnit4Provider.execute(JUnit4Provider.java:236)
	at org.apache.maven.surefire.junit4.JUnit4Provider.executeTestSet(JUnit4Provider.java:134)
	at org.apache.maven.surefire.junit4.JUnit4Provider.invoke(JUnit4Provider.java:113)
	at sun.reflect.NativeMethodAccessorImpl.invoke0(Native Method)
	at sun.reflect.NativeMethodAccessorImpl.invoke(NativeMethodAccessorImpl.java:39)
	at sun.reflect.DelegatingMethodAccessorImpl.invoke(DelegatingMethodAccessorImpl.java:25)
	at java.lang.reflect.Method.invoke(Method.java:597)
	at org.apache.maven.surefire.util.ReflectionUtils.invokeMethodWithArray(ReflectionUtils.java:189)
	at org.apache.maven.surefire.booter.ProviderFactory$ProviderProxy.invoke(ProviderFactory.java:165)
	at org.apache.maven.surefire.booter.ProviderFactory.invokeProvider(ProviderFactory.java:85)
	at org.apache.maven.surefire.booter.ForkedBooter.runSuitesInProcess(ForkedBooter.java:103)
	at org.apache.maven.surefire.booter.ForkedBooter.main(ForkedBooter.java:74)
Caused by: org.h2.jdbc.JdbcSQLException: The connection was not closed by the application and is garbage collected [90018-168]
	at org.h2.message.DbException.getJdbcSQLException(DbException.java:329)
	... 39 more
11-19 14:35:19 jdbc[2]: exception
org.h2.jdbc.JdbcSQLException: Table "USERS" not found; SQL statement:
drop table Users [42102-168]
11-19 14:35:19 jdbc[2]: exception
org.h2.jdbc.JdbcSQLException: The object is already closed [90007-168]
	at org.h2.message.DbException.getJdbcSQLException(DbException.java:329)
	at org.h2.message.DbException.get(DbException.java:169)
	at org.h2.message.DbException.get(DbException.java:146)
	at org.h2.message.DbException.get(DbException.java:135)
	at org.h2.jdbc.JdbcConnection.checkClosed(JdbcConnection.java:1381)
	at org.h2.jdbc.JdbcConnection.checkClosed(JdbcConnection.java:1359)
	at org.h2.jdbc.JdbcConnection.createStatement(JdbcConnection.java:189)
	at org.apache.airavata.services.registry.rest.security.local.LocalUserStoreTest.createTable(LocalUserStoreTest.java:36)
	at org.apache.airavata.services.registry.rest.security.local.LocalUserStoreTest.setUp(LocalUserStoreTest.java:66)
	at junit.framework.TestCase.runBare(TestCase.java:132)
	at junit.framework.TestResult$1.protect(TestResult.java:110)
	at junit.framework.TestResult.runProtected(TestResult.java:128)
	at junit.framework.TestResult.run(TestResult.java:113)
	at junit.framework.TestCase.run(TestCase.java:124)
	at junit.framework.TestSuite.runTest(TestSuite.java:232)
	at junit.framework.TestSuite.run(TestSuite.java:227)
	at org.junit.internal.runners.JUnit38ClassRunner.run(JUnit38ClassRunner.java:83)
	at org.junit.runner.JUnitCore.run(JUnitCore.java:157)
	at com.intellij.junit4.JUnit4IdeaTestRunner.startRunnerWithArgs(JUnit4IdeaTestRunner.java:76)
	at com.intellij.rt.execution.junit.JUnitStarter.prepareStreamsAndStart(JUnitStarter.java:195)
	at com.intellij.rt.execution.junit.JUnitStarter.main(JUnitStarter.java:63)
	at sun.reflect.NativeMethodAccessorImpl.invoke0(Native Method)
	at sun.reflect.NativeMethodAccessorImpl.invoke(NativeMethodAccessorImpl.java:39)
	at sun.reflect.DelegatingMethodAccessorImpl.invoke(DelegatingMethodAccessorImpl.java:25)
	at java.lang.reflect.Method.invoke(Method.java:597)
	at com.intellij.rt.execution.application.AppMain.main(AppMain.java:120)
11-19 14:35:31 jdbc[2]: exception
org.h2.jdbc.JdbcSQLException: Table "USERS" not found; SQL statement:
drop table Users [42102-168]
11-19 14:35:31 jdbc[2]: exception
org.h2.jdbc.JdbcSQLException: The object is already closed [90007-168]
	at org.h2.message.DbException.getJdbcSQLException(DbException.java:329)
	at org.h2.message.DbException.get(DbException.java:169)
	at org.h2.message.DbException.get(DbException.java:146)
	at org.h2.message.DbException.get(DbException.java:135)
	at org.h2.jdbc.JdbcConnection.checkClosed(JdbcConnection.java:1381)
	at org.h2.jdbc.JdbcConnection.checkClosed(JdbcConnection.java:1359)
	at org.h2.jdbc.JdbcConnection.createStatement(JdbcConnection.java:189)
	at org.apache.airavata.services.registry.rest.security.local.LocalUserStoreTest.createTable(LocalUserStoreTest.java:36)
	at org.apache.airavata.services.registry.rest.security.local.LocalUserStoreTest.setUp(LocalUserStoreTest.java:66)
	at junit.framework.TestCase.runBare(TestCase.java:132)
	at junit.framework.TestResult$1.protect(TestResult.java:110)
	at junit.framework.TestResult.runProtected(TestResult.java:128)
	at junit.framework.TestResult.run(TestResult.java:113)
	at junit.framework.TestCase.run(TestCase.java:124)
	at junit.framework.TestSuite.runTest(TestSuite.java:232)
	at junit.framework.TestSuite.run(TestSuite.java:227)
	at org.junit.internal.runners.JUnit38ClassRunner.run(JUnit38ClassRunner.java:83)
	at org.junit.runner.JUnitCore.run(JUnitCore.java:157)
	at com.intellij.junit4.JUnit4IdeaTestRunner.startRunnerWithArgs(JUnit4IdeaTestRunner.java:76)
	at com.intellij.rt.execution.junit.JUnitStarter.prepareStreamsAndStart(JUnitStarter.java:195)
	at com.intellij.rt.execution.junit.JUnitStarter.main(JUnitStarter.java:63)
	at sun.reflect.NativeMethodAccessorImpl.invoke0(Native Method)
	at sun.reflect.NativeMethodAccessorImpl.invoke(NativeMethodAccessorImpl.java:39)
	at sun.reflect.DelegatingMethodAccessorImpl.invoke(DelegatingMethodAccessorImpl.java:25)
	at java.lang.reflect.Method.invoke(Method.java:597)
	at com.intellij.rt.execution.application.AppMain.main(AppMain.java:120)
11-19 14:36:26 jdbc[2]: exception
org.h2.jdbc.JdbcSQLException: Table "USERS" not found; SQL statement:
drop table Users [42102-168]
